Workbook

Sheet Guided Project Count and Marks
A1: ID number | B1: Guided Projects Count | C1: Marks
A2: 102483080 | B2: =COUNTIF('Form Responses 1'!D:D,A2) -> 17 | C2: =IF(B2>24,8,floor(B2/3,1)) -> 5
A3: 102303794 | B3: =COUNTIF('Form Responses 1'!D:D,A3) -> 16 | C3: =IF(B3>24,8,floor(B3/3,1)) -> 5
A4: 102303113 | B4: =COUNTIF('Form Responses 1'!D:D,A4) -> 15 | C4: =IF(B4>24,8,floor(B4/3,1)) -> 5
A5: 102303437 | B5: =COUNTIF('Form Responses 1'!D:D,A5) -> 12 | C5: =IF(B5>24,8,floor(B5/3,1)) -> 4
A6: 102303157 | B6: =COUNTIF('Form Responses 1'!D:D,A6) -> 12 | C6: =IF(B6>24,8,floor(B6/3,1)) -> 4
A7: 102313059 | B7: =COUNTIF('Form Responses 1'!D:D,A7) -> 11 | C7: =IF(B7>24,8,floor(B7/3,1)) -> 3
A8: 102497023 | B8: =COUNTIF('Form Responses 1'!D:D,A8) -> 10 | C8: =IF(B8>24,8,floor(B8/3,1)) -> 3
A9: 102317208 | B9: =COUNTIF('Form Responses 1'!D:D,A9) -> 10 | C9: =IF(B9>24,8,floor(B9/3,1)) -> 3
A10: 102317094 | B10: =COUNTIF('Form Responses 1'!D:D,A10) -> 10 | C10: =IF(B10>24,8,floor(B10/3,1)) -> 3
A11: 102497014 | B11: =COUNTIF('Form Responses 1'!D:D,A11) -> 9 | C11: =IF(B11>24,8,floor(B11/3,1)) -> 3
A12: 102497010 | B12: =COUNTIF('Form Responses 1'!D:D,A12) -> 9 | C12: =IF(B12>24,8,floor(B12/3,1)) -> 3
A13: 102317240 | B13: =COUNTIF('Form Responses 1'!D:D,A13) -> 9 | C13: =IF(B13>24,8,floor(B13/3,1)) -> 3
... A507: 102103383 | B507: =COUNTIF('Form Responses 1'!D:D,A507) -> 0 | C507: =IF(B507>24,8,floor(B507/3,1)) -> 0

Sheet Wrong Submissions
A1: Timestamp | B1: Email Address | C1: Full Name of the Student | D1: Roll Number of the Student | E1: Coursera completion certificate link (Coursera Link only, no other text) (Certificate must shared in public mode) | F1: LinkedIn Post Link ( LinkedIn Link only, no other text) (Coursera Certificate must be shared on LinkedIn with your learning experience and following HashTags) #TIET #ThaparUniversity #ThaparOutcomeBasedLearning #ThaparCoursera #Coursera #UCS654_Predictive_Analytics | G1: Decision | H1: C1 | I1: C2 | J1: Total
A2: 46032.707 | B2: kkumud_be23@thapar.edu | C2: Kumud | D2: 102316088 | E2: https://coursera.org/share/a1540db1fb527d46d0032947710dc29a AND https://coursera.org/share/9a61cb1ca3690e8ff77327debd207d03 | F2: https://www.linkedin.com/posts/kumud-grover-425a3b326_tiet-thaparinstitute-thaparstudent-activity-7415713820473528320-jZJV?utm_source=social_share_send&utm_medium=android_app&rcm=ACoAAFJhF50BqPn8EfYDQT3hQ-9Sy8fiwJNvzSo&utm_campaign=whatsapp AND https://www.linkedin.com/posts/kumud-grover-425a3b326_tiet-thaparinstitute-thaparstudent-activity-7415327972636708865-bJHq?utm_source=social_share_send&utm_medium=android_app&rcm=ACoAAFJhF50BqPn8EfYDQT3hQ-9Sy8fiwJNvzSo&utm_campaign=whatsapp | G2: 0 | H2: =(LEN(E2)-LEN(SUBSTITUTE(E2,"coursera","")))/LEN("coursera") -> 2 | I2: =(LEN(F2)-LEN(SUBSTITUTE(F2,"linkedin","")))/LEN("linkedin") -> 2 | J2: =SUM(H2:I2) -> 4
A3: 46032.726 | B3: aranjan1_be23@thapar.edu | C3: Aryan Ranjan | D3: 102303528 | E3: https://coursera.org/share/a2f0ee6943b95ae48c190d7c8073b546 https://coursera.org/share/b18c7ad1336374beb9a2126a4991129c | F3: https://www.linkedin.com/feed/update/urn:li:activity:7415720275117281280/ https://www.linkedin.com/feed/update/urn:li:activity:7415721781635788800/ | G3: 0 | H3: =(LEN(E3)-LEN(SUBSTITUTE(E3,"coursera","")))/LEN("coursera") -> 2 | I3: =(LEN(F3)-LEN(SUBSTITUTE(F3,"linkedin","")))/LEN("linkedin") -> 2 | J3: =SUM(H3:I3) -> 4
A4: 46032.967 | B4: piyush11nm028jss@gmail.com | C4: Piyush Taneja | D4: 102303307 | E4: Project-1:https://coursera.org/share/dc57b063efe954b017a2e743dba2bf6e,Project-2:https://coursera.org/share/e3053fe31ebc4aa7b9d8ac3d696ae604, | F4: Project-1:https://www.linkedin.com/posts/piyush-taneja-20b915304_data-visualization-using-bokeh-activity-7415809048433987584-43s1?utm_source=share&utm_medium=member_ios&rcm=ACoAAE273-sBKlNsbj1JJ3DKMObbMsw2vJ0fkWc,Project-2:https://www.linkedin.com/posts/piyush-taneja-20b915304_tweet-emotion-recognition-with-tensorflow-activity-7415809544540655616-T4OW?utm_source=share&utm_medium=member_ios&rcm=ACoAAE273-sBKlNsbj1JJ3DKMObbMsw2vJ0fkWc | G4: 0 | H4: =(LEN(E4)-LEN(SUBSTITUTE(E4,"coursera","")))/LEN("coursera") -> 2 | I4: =(LEN(F4)-LEN(SUBSTITUTE(F4,"linkedin","")))/LEN("linkedin") -> 2 | J4: =SUM(H4:I4) -> 4
A5: 46032.978 | B5: vsrivastva_be23@thapar.edu | C5: Vaibhav Srivastva | D5: 102316037 | E5: https://coursera.org/share/9ce4fc9b1364152d06ac71a117d0a8e1, https://coursera.org/share/158ca417c7a8648895be02e470aaf0fa | F5: https://www.linkedin.com/posts/vaibhav-srivastva_tiet-thaparuniversity-thaparoutcomebasedlearning-activity-7415112562389798912-qBPg?utm_source=share&utm_medium=member_desktop&rcm=ACoAAEkzASwBFTKWwl04fYnDkBPe0UXOfZ7kdr8, https://www.linkedin.com/posts/vaibhav-srivastva_tiet-thaparuniversity-thaparoutcomebasedlearning-activity-7414307642585591808-2rfh?utm_source=share&utm_medium=member_desktop&rcm=ACoAAEkzASwBFTKWwl04fYnDkBPe0UXOfZ7kdr8 | G5: 0 | H5: =(LEN(E5)-LEN(SUBSTITUTE(E5,"coursera","")))/LEN("coursera") -> 2 | I5: =(LEN(F5)-LEN(SUBSTITUTE(F5,"linkedin","")))/LEN("linkedin") -> 2 | J5: =SUM(H5:I5) -> 4
A6: 46032.99 | B6: lbhatia_be23@thapar.edu | C6: Lovepreet Bhatia | D6: 102303335 | E6: https://coursera.org/share/7701bcce5efbbe8ea652273d08031ab1 , https://coursera.org/share/4a5df9ee5233eff0d3d3828076afcc2d | F6: https://www.linkedin.com/posts/lovepreet-bhatia-16a66838b_google-analytics-activity-7415808996894248960-UpoR?utm_source=share&utm_medium=member_desktop&rcm=ACoAAGAt5fMBGFx611lB_AIC3jzy0T1_acWPX8g , https://www.linkedin.com/posts/lovepreet-bhatia-16a66838b_working-with-bigquery-activity-7415808589497282560-Y8uH?utm_source=share&utm_medium=member_desktop&rcm=ACoAAGAt5fMBGFx611lB_AIC3jzy0T1_acWPX8g | G6: 0 | H6: =(LEN(E6)-LEN(SUBSTITUTE(E6,"coursera","")))/LEN("coursera") -> 2 | I6: =(LEN(F6)-LEN(SUBSTITUTE(F6,"linkedin","")))/LEN("linkedin") -> 2 | J6: =SUM(H6:I6) -> 4
A7: 46033.523 | B7: aakshita_be23@thapar.edu | C7: Akshita | D7: 102303531 | E7: Working with BigQuery (Coursera Project): https://coursera.org/verify/IPWYR3UYJEDG Build a CI/CD Pipeline with Docker (Coursera Project): https://coursera.org/verify/P96JEL85JXAI | F7: Working with BigQuery(Coursera Project): https://www.linkedin.com/posts/akshita-verma-272a9836b_coursera-certificate-working-with-bigquery-activity-7415664618649460736-8lh6?utm_source=share&utm_medium=member_android&rcm=ACoAAFvRuHYBP2UdXoBzjDdHWHfhcZw7Jp57Gls Build a CI/CD Pipeline with Docker (Coursera Project): https://www.linkedin.com/posts/akshita-verma-272a9836b_build-a-cicd-pipeline-with-docker-coursera-activity-7416004386545377280-hRom?utm_source=share&utm_medium=member_android&rcm=ACoAAFvRuHYBP2UdXoBzjDdHWHfhcZw7Jp57Gls | G7: 0 | H7: =(LEN(E7)-LEN(SUBSTITUTE(E7,"coursera","")))/LEN("coursera") -> 2 | I7: =(LEN(F7)-LEN(SUBSTITUTE(F7,"linkedin","")))/LEN("linkedin") -> 2 | J7: =SUM(H7:I7) -> 4
A8: 46033.591 | B8: manyagarg453@gmail.com | C8: Manya Garg | D8: 102303254 | E8: https://www.coursera.org/account/accomplishments/records/K492RR782XYU ,https://www.coursera.org/account/accomplishments/records/AEW2DHI5B9KE | F8: https://www.linkedin.com/posts/manya-garg-452498295_completion-certificate-for-working-with-bigquery-activity-7416035717367230464-j4Uo?utm_source=share&utm_medium=member_desktop&rcm=ACoAAEdw0X4BhRB4Yof3Vj1ViCDZk_Yk8ryLzUg , https://www.linkedin.com/posts/manya-garg-452498295_completion-certificate-for-build-a-cicd-activity-7416035272037085184-YDLm?utm_source=share&utm_medium=member_desktop&rcm=ACoAAEdw0X4BhRB4Yof3Vj1ViCDZk_Yk8ryLzUg | G8: 0 | H8: =(LEN(E8)-LEN(SUBSTITUTE(E8,"coursera","")))/LEN("coursera") -> 2 | I8: =(LEN(F8)-LEN(SUBSTITUTE(F8,"linkedin","")))/LEN("linkedin") -> 2 | J8: =SUM(H8:I8) -> 4
A9: 46033.598 | B9: vkbansal902@gmail.com | C9: vishesh kumar bansal | D9: 102316085 | E9: https://coursera.org/share/41736b0faf22fdfe3ab9282b69f991fd , https://coursera.org/share/64ec3d0d71d8f490797108c7b983b190 | F9: https://www.linkedin.com/posts/vishesh-kumar-bansal-833a0728a_tiet-thaparuniversity-thaparoutcomebasedlearning-activity-7416038691980107776-ZY29?utm_source=share&utm_medium=member_desktop&rcm=ACoAAEZFy-cBExBmjqFJHIt9-P19T-ubk8318rk , https://www.linkedin.com/posts/vishesh-kumar-bansal-833a0728a_tiet-thaparuniversity-thaparoutcomebasedlearning-activity-7416037276129894400-0H5k?utm_source=share&utm_medium=member_desktop&rcm=ACoAAEZFy-cBExBmjqFJHIt9-P19T-ubk8318rk | G9: 0 | H9: =(LEN(E9)-LEN(SUBSTITUTE(E9,"coursera","")))/LEN("coursera") -> 2 | I9: =(LEN(F9)-LEN(SUBSTITUTE(F9,"linkedin","")))/LEN("linkedin") -> 2 | J9: =SUM(H9:I9) -> 4
A10: 46033.644 | B10: rduggal_be23@thapar.edu | C10: Raiza Duggal | D10: 102303068 | E10: 1)https://coursera.org/share/dc1b93c955db9d151fd001509b22f4fd 2)https://coursera.org/share/57180b3c523113024d1f9194fe257baf | F10: 1)https://www.linkedin.com/posts/raiza-duggal-068740323_tiet-thaparuniversity-thaparoutcomebasedlearning-activity-7416054584772624384-VRO_?utm_source=share&utm_medium=member_desktop&rcm=ACoAAFHNCFABtwP6Sv2lw9MlVwsLG8YwlA4msYI 2)https://www.linkedin.com/posts/raiza-duggal-068740323_tiet-thaparuniversity-thaparoutcomebasedlearning-activity-7416055067893616640-uTbH?utm_source=share&utm_medium=member_desktop&rcm=ACoAAFHNCFABtwP6Sv2lw9MlVwsLG8YwlA4msYI | G10: 0 | H10: =(LEN(E10)-LEN(SUBSTITUTE(E10,"coursera","")))/LEN("coursera") -> 2 | I10: =(LEN(F10)-LEN(SUBSTITUTE(F10,"linkedin","")))/LEN("linkedin") -> 2 | J10: =SUM(H10:I10) -> 4
A11: 46033.686 | B11: agarg_be23@thapar.edu | C11: Aastha Garg | D11: 102313059 | E11: 1. https://coursera.org/verify/YSNH7OZ6IO0Z 2. https://coursera.org/verify/PIIHGJ93NHUZ | F11: 1. https://www.linkedin.com/posts/aastha-gargg_tiet-thaparinstitute-thaparuniversity-activity-7416067811338280960-mbIN?utm_source=share&utm_medium=member_android&rcm=ACoAAFjyqzEBX6lEOpP3xZKH-93udiyNgmSQ3lM 2. https://www.linkedin.com/posts/aastha-gargg_tiet-thaparinstitute-thaparuniversity-activity-7416042597602705408-nwPe?utm_source=share&utm_medium=member_android&rcm=ACoAAFjyqzEBX6lEOpP3xZKH-93udiyNgmSQ3lM | G11: 0 | H11: =(LEN(E11)-LEN(SUBSTITUTE(E11,"coursera","")))/LEN("coursera") -> 2 | I11: =(LEN(F11)-LEN(SUBSTITUTE(F11,"linkedin","")))/LEN("linkedin") -> 2 | J11: =SUM(H11:I11) -> 4
A12: 46033.745 | B12: vsharda_be23@thapar.edu | C12: Vinesh Sharda | D12: 102316066 | E12: https://coursera.org/share/6d6e9d5c155db0a2cb77c0b3c4afc501 & https://coursera.org/share/7eb2d71c22ac7f68a2afc0671c8ba8f9 | F12: https://www.linkedin.com/feed/update/urn:li:activity:7416059723533242368/ & https://www.linkedin.com/feed/update/urn:li:activity:7416089323843801088/ | G12: 0 | H12: =(LEN(E12)-LEN(SUBSTITUTE(E12,"coursera","")))/LEN("coursera") -> 2 | I12: =(LEN(F12)-LEN(SUBSTITUTE(F12,"linkedin","")))/LEN("linkedin") -> 2 | J12: =SUM(H12:I12) -> 4
A13: 46033.783 | B13: ddrishti_be23@thapar.edu | C13: Drishti | D13: 102316073 | E13: https://coursera.org/share/ec49eed3517494dcd8299d2853413eab, https://coursera.org/share/3722273356ce61bcc632022199408064 | F13: https://www.linkedin.com/posts/drishti-singla-b447a42a6_tiet-thaparuniversity-thaparoutcomebasedlearning-activity-7416102486790291456-Ovw6?utm_source=share&utm_medium=member_desktop&rcm=ACoAAEnMv2QBBcdbW8RSfaEJOV0lNt0LOOiv-hM https://www.linkedin.com/posts/drishti-singla-b447a42a6_tiet-thaparuniversity-thaparoutcomebasedlearning-activity-7416103528722534400-cVBX?utm_source=share&utm_medium=member_desktop&rcm=ACoAAEnMv2QBBcdbW8RSfaEJOV0lNt0LOOiv-hM | G13: 0 | H13: =(LEN(E13)-LEN(SUBSTITUTE(E13,"coursera","")))/LEN("coursera") -> 2 | I13: =(LEN(F13)-LEN(SUBSTITUTE(F13,"linkedin","")))/LEN("linkedin") -> 2 | J13: =SUM(H13:I13) -> 4
... A250: 46054.678 | B250: rrachit_be23@thapar.edu | C250: Rachit | D250: 102303495 | E250: https://coursera.org/share/87f0f163fd59fab46042b2cd15e8786d | F250: https://www.linkedin.com/posts/rachit-mahajan-1326492a0_tiet-thaparinstitute-thaparuniversity-activity-7418749668941115392-PDAM?utm_source=share&utm_medium=member_desktop&rcm=ACoAAEi1yXYBiMIbtJXtKc9efrQGN8dUX4BMwWw | G250: 0 | H250: =(LEN(E250)-LEN(SUBSTITUTE(E250,"coursera","")))/LEN("coursera") -> 1 | I250: =(LEN(F250)-LEN(SUBSTITUTE(F250,"linkedin","")))/LEN("linkedin") -> 1 | J250: =SUM(H250:I250) -> 2
A251: 46041.087 | B251: ajain9_be23@thapar.edu | C251: 102316056 | D251: Atishay jain | E251: https://coursera.org/share/ed1434464d3b9771d65bff22d1880397 | F251: https://www.linkedin.com/posts/atishay-jain-671223312_tiet-thaparinstitute-thaparuniversity-share-7418740927856357376-vptO?utm_source=share&utm_medium=member_desktop&rcm=ACoAAE9pMfUBmpJLZ7yi6VRfUyWLGqJEzV6CHCc | G251: 0 | H251: =(LEN(E251)-LEN(SUBSTITUTE(E251,"coursera","")))/LEN("coursera") -> 1 | I251: =(LEN(F251)-LEN(SUBSTITUTE(F251,"linkedin","")))/LEN("linkedin") -> 1 | J251: =SUM(H251:I251) -> 2
A252: 46054.663 | B252: kkaur3_be23@thapar.edu | C252: Khushveer Kaur | D252: 102303327 | E252: https://coursera.org/share/1154c5eab03cda5082c4b4e9100da111 | F252: https://www.linkedin.com/posts/khushveer-kaur-27b460321_tiet-thaparuniversity-thaparoutcomebasedlearning-activity-7420799919231365120-tVdF?utm_source=share&utm_medium=member_desktop&rcm=ACoAAFFnJ38BDy2j3bWMPxtTwPtiEO1ksVqOYZs | G252: 0 | H252: =(LEN(E252)-LEN(SUBSTITUTE(E252,"coursera","")))/LEN("coursera") -> 1 | I252: =(LEN(F252)-LEN(SUBSTITUTE(F252,"linkedin","")))/LEN("linkedin") -> 1 | J252: =SUM(H252:I252) -> 2
A253: 46054.664 | B253: kkaur3_be23@thapar.edu | C253: Khushveer Kaur | D253: 102303327 | E253: https://coursera.org/share/a4ef0afaa28d8419e0d7f06f1346533a | F253: https://www.linkedin.com/posts/khushveer-kaur-27b460321_tiet-thaparuniversity-thaparoutcomebasedlearning-activity-7420801867498172416-KwZw?utm_source=share&utm_medium=member_desktop&rcm=ACoAAFFnJ38BDy2j3bWMPxtTwPtiEO1ksVqOYZs | G253: 0 | H253: =(LEN(E253)-LEN(SUBSTITUTE(E253,"coursera","")))/LEN("coursera") -> 1 | I253: =(LEN(F253)-LEN(SUBSTITUTE(F253,"linkedin","")))/LEN("linkedin") -> 1 | J253: =SUM(H253:I253) -> 2
A254: 46054.679 | B254: rrachit_be23@thapar.edu | C254: Rachit | D254: 102303495 | E254: https://coursera.org/share/bc7a018001aa3298c92c6e0383def84a | F254: https://www.linkedin.com/posts/rachit-mahajan-1326492a0_completion-certificate-for-overview-of-data-activity-7421215980493680640-hxyh?utm_source=share&utm_medium=member_desktop&rcm=ACoAAEi1yXYBiMIbtJXtKc9efrQGN8dUX4BMwWw | G254: 0 | H254: =(LEN(E254)-LEN(SUBSTITUTE(E254,"coursera","")))/LEN("coursera") -> 1 | I254: =(LEN(F254)-LEN(SUBSTITUTE(F254,"linkedin","")))/LEN("linkedin") -> 1 | J254: =SUM(H254:I254) -> 2
A255: 46054.68 | B255: rrachit_be23@thapar.edu | C255: Rachit | D255: 102303495 | E255: https://coursera.org/share/80ba34271c2f4f561168d5370e631bc0 | F255: https://www.linkedin.com/posts/rachit-mahajan-1326492a0_completion-certificate-for-mastering-data-activity-7421207033489674241-TRr3?utm_source=share&utm_medium=member_desktop&rcm=ACoAAEi1yXYBiMIbtJXtKc9efrQGN8dUX4BMwWw | G255: 0 | H255: =(LEN(E255)-LEN(SUBSTITUTE(E255,"coursera","")))/LEN("coursera") -> 1 | I255: =(LEN(F255)-LEN(SUBSTITUTE(F255,"linkedin","")))/LEN("linkedin") -> 1 | J255: =SUM(H255:I255) -> 2
A256: 46047.917 | B256: dsethi_be23@thapar.edu | C256: Dhruv Sethi | D256: 102303785 | E256: Statistics For Data Science - https://coursera.org/share/fe1b31f5ebd63b5e5bf15e3f5f1b37c2 | F256: https://www.linkedin.com/posts/dhruv-sethi590_tiet-thaparuniversity-thaparoutcomebasedlearning-activity-7421202727214587904-8qfP?utm_source=share&utm_medium=member_desktop&rcm=ACoAAFCzcyMBbnA1s4fkO9C6OA-XWvaxcdMWGZk | G256: 0 | H256: =(LEN(E256)-LEN(SUBSTITUTE(E256,"coursera","")))/LEN("coursera") -> 1 | I256: =(LEN(F256)-LEN(SUBSTITUTE(F256,"linkedin","")))/LEN("linkedin") -> 1 | J256: =SUM(H256:I256) -> 2
A257: 46047.919 | B257: dsethi_be23@thapar.edu | C257: Dhruv Sethi | D257: 102303785 | E257: Advanced Relational Database and SQL - https://coursera.org/share/171de17e4bbbadb74f516ec7970721a5 | F257: https://www.linkedin.com/posts/dhruv-sethi590_tiet-thaparuniversity-thaparoutcomebasedlearning-activity-7421202727214587904-8qfP?utm_source=share&utm_medium=member_desktop&rcm=ACoAAFCzcyMBbnA1s4fkO9C6OA-XWvaxcdMWGZk | G257: 0 | H257: =(LEN(E257)-LEN(SUBSTITUTE(E257,"coursera","")))/LEN("coursera") -> 1 | I257: =(LEN(F257)-LEN(SUBSTITUTE(F257,"linkedin","")))/LEN("linkedin") -> 1 | J257: =SUM(H257:I257) -> 2
A258: 46048.913 | B258: rchopra_be23@thapar.edu | C258: Rakshit Chopra | D258: 102303921 | E258: https://coursera.org/share/8740d60b19cbd5f1b091a70d49f8c1c0 | F258: https://www.linkedin.com/posts/rakshit-chopra-0a6709269_completion-certificate-for-react-foundations-activity-7421292345830125568-um_W?utm_source=share&utm_medium=member_desktop&rcm=ACoAAEHHYT4BjEPQczBHCazqNEPVM0pf92reMlQhttps://coursera.org/share/8740d60b19cbd5f1b091a70d49f8c1c0 | G258: 0 | H258: =(LEN(E258)-LEN(SUBSTITUTE(E258,"coursera","")))/LEN("coursera") -> 1 | I258: =(LEN(F258)-LEN(SUBSTITUTE(F258,"linkedin","")))/LEN("linkedin") -> 1 | J258: =SUM(H258:I258) -> 2
A259: 46048.914 | B259: rchopra_be23@thapar.edu | C259: Rakshit Chopra | D259: 102303921 | E259: https://coursera.org/share/84f8763bb8cd8c3ad44bf0131d5ab760 | F259: https://www.linkedin.com/posts/rakshit-chopra-0a6709269_completion-certificate-for-software-architecture-activity-7421263812156157952-8oJc?utm_source=share&utm_medium=member_desktop&rcm=ACoAAEHHYT4BjEPQczBHCazqNEPVM0pf92reMlQhttps://coursera.org/share/84f8763bb8cd8c3ad44bf0131d5ab760 | G259: 0 | H259: =(LEN(E259)-LEN(SUBSTITUTE(E259,"coursera","")))/LEN("coursera") -> 1 | I259: =(LEN(F259)-LEN(SUBSTITUTE(F259,"linkedin","")))/LEN("linkedin") -> 1 | J259: =SUM(H259:I259) -> 2
A260: 46052.01 | B260: saanviwadhwa09@gmail.com | C260: Saanvi Wadhwa | D260: 102483080 | E260: https://www.linkedin.com/posts/saanvi-wadhwa-366b7a302_tiet-thaparuniversity-thaparcoursera-activity-7422709906190913536-8ILN?utm_source=share&utm_medium=member_desktop&rcm=ACoAAE1qYH4BJe1EK-Fy9yHnNT72ERPWclZAZ8s | F260: https://www.linkedin.com/posts/saanvi-wadhwa-366b7a302_tiet-thaparuniversity-thaparcoursera-activity-7422709906190913536-8ILN?utm_source=share&utm_medium=member_desktop&rcm=ACoAAE1qYH4BJe1EK-Fy9yHnNT72ERPWclZAZ8s | G260: 0 | H260: =(LEN(E260)-LEN(SUBSTITUTE(E260,"coursera","")))/LEN("coursera") -> 1 | I260: =(LEN(F260)-LEN(SUBSTITUTE(F260,"linkedin","")))/LEN("linkedin") -> 1 | J260: =SUM(H260:I260) -> 2
A261: 46053.454 | B261: sagarwal2_be23@thapar.edu | C261: Suwan Agarwal | D261: 102317217 | E261: BIG QUERY: https://coursera.org/share/37d5efe8e8d18c39182be0539b9af51b | F261: https://www.linkedin.com/posts/suwan-agarwal-6aa2b02aa_completion-certificate-for-working-with-bigquery-activity-7419084548090580994-h_2J?utm_source=share&utm_medium=member_desktop&rcm=ACoAAEpwNuIBo7BJsPSn0JJxuNqbYkdcs465kDY | G261: 0 | H261: =(LEN(E261)-LEN(SUBSTITUTE(E261,"coursera","")))/LEN("coursera") -> 1 | I261: =(LEN(F261)-LEN(SUBSTITUTE(F261,"linkedin","")))/LEN("linkedin") -> 1 | J261: =SUM(H261:I261) -> 2
A262: 46053.456 | B262: sagarwal2_be23@thapar.edu | C262: Suwan Agarwal | D262: 102317217 | E262: Image Classification: https://coursera.org/share/908d323cc296d67870d5269640449f10 | F262: https://www.linkedin.com/posts/suwan-agarwal-6aa2b02aa_completion-certificate-for-basic-image-classification-activity-7419084275746144256-0T_9?utm_source=share&utm_medium=member_desktop&rcm=ACoAAEpwNuIBo7BJsPSn0JJxuNqbYkdcs465kDY | G262: 0 | H262: =(LEN(E262)-LEN(SUBSTITUTE(E262,"coursera","")))/LEN("coursera") -> 1 | I262: =(LEN(F262)-LEN(SUBSTITUTE(F262,"linkedin","")))/LEN("linkedin") -> 1 | J262: =SUM(H262:I262) -> 2
A263: 46053.52 | B263: aananya1_be23@thapar.edu | C263: Ananya | D263: 102303160 | E263: 1. https://coursera.org/share/4e2ff3d2b59db08333140b0b4768d9be | F263: https://www.linkedin.com/posts/gladananya_tiet-thaparinstitute-thaparuniversity-activity-7416190423255105536-Nd7z?utm_source=share&utm_medium=member_desktop&rcm=ACoAAEXhJ_QBP07UFHC84gk_VevzmpO7o1n2-kY | G263: 0 | H263: =(LEN(E263)-LEN(SUBSTITUTE(E263,"coursera","")))/LEN("coursera") -> 1 | I263: =(LEN(F263)-LEN(SUBSTITUTE(F263,"linkedin","")))/LEN("linkedin") -> 1 | J263: =SUM(H263:I263) -> 2
... A266: 46053.522 | B266: aananya1_be23@thapar.edu | C266: Ananya | D266: 102303160 | E266: 2.https://coursera.org/share/83daa1bf6c697c2cfde9310fd79b2f98 | F266: https://www.linkedin.com/posts/gladananya_tiet-thaparuniversity-thaparoutcomebasedlearning-activity-7422009110134710273-bMYP?utm_source=share&utm_medium=member_desktop&rcm=ACoAAEXhJ_QBP07UFHC84gk_VevzmpO7o1n2-kY | G266: 0 | H266: =(LEN(E266)-LEN(SUBSTITUTE(E266,"coursera","")))/LEN("coursera") -> 1 | I266: =(LEN(F266)-LEN(SUBSTITUTE(F266,"linkedin","")))/LEN("linkedin") -> 1 | J266: =SUM(H266:I266) -> 2
A267: 46053.798 | B267: ysharma1_be23@thapar.edu | C267: yashika sharma | D267: yashika sharma | E267: https://coursera.org/share/399e19b911e2d3594dc28a21c772f814 | F267: https://www.linkedin.com/posts/yashika-sharma-785980286_tiet-thaparuniversity-thaparoutcomebasedlearning-activity-7416150763900518400-MoXZ?utm_source=social_share_send&utm_medium=member_desktop_web&rcm=ACoAAEWOGFUBDP8UI3bYLMEpP-xLWSr_yKhT5Yg | G267: 0 | H267: =(LEN(E267)-LEN(SUBSTITUTE(E267,"coursera","")))/LEN("coursera") -> 1 | I267: =(LEN(F267)-LEN(SUBSTITUTE(F267,"linkedin","")))/LEN("linkedin") -> 1 | J267: =SUM(H267:I267) -> 2
A268: 46053.879 | B268: skumari_be23@thapar.edu | C268: Saumya Kumari | D268: 102303161 | E268: https://coursera.org/share/a3611b486b6855661a27ad20e49e813d | F268: https://www.linkedin.com/posts/saumya-kumari-6263b9355_tiet-thaparinstitute-thaparuniversity-activity-7420465765914697728-xsEz?utm_source=share&utm_medium=member_desktop&rcm=ACoAAFiDrz4Bns2yLsJGj_n4mQPA3ihv3zNbTGU | G268: 0 | H268: =(LEN(E268)-LEN(SUBSTITUTE(E268,"coursera","")))/LEN("coursera") -> 1 | I268: =(LEN(F268)-LEN(SUBSTITUTE(F268,"linkedin","")))/LEN("linkedin") -> 1 | J268: =SUM(H268:I268) -> 2
A269: 46054.488 | B269: skumari_be23@thapar.edu | C269: Saumya Kumari | D269: 102303161 | E269: https://coursera.org/share/e3cdf39abaf5ca101c211df24f868be2 | F269: https://www.linkedin.com/posts/saumya-kumari-6263b9355_tiet-thaparinstitute-thaparuniversity-activity-7418669094536626176-HVCK?utm_source=share&utm_medium=member_desktop&rcm=ACoAAFiDrz4Bns2yLsJGj_n4mQPA3ihv3zNbTGU | G269: 0 | H269: =(LEN(E269)-LEN(SUBSTITUTE(E269,"coursera","")))/LEN("coursera") -> 1 | I269: =(LEN(F269)-LEN(SUBSTITUTE(F269,"linkedin","")))/LEN("linkedin") -> 1 | J269: =SUM(H269:I269) -> 2
A270: 46054.489 | B270: skumari_be23@thapar.edu | C270: Saumya Kumari | D270: 102303161 | E270: https://coursera.org/share/767481a88ecf50a28bae92fd703279bb | F270: https://www.linkedin.com/posts/saumya-kumari-6263b9355_tiet-thaparinstitute-thaparuniversity-activity-7415794806544695296-kzZl?utm_source=share&utm_medium=member_desktop&rcm=ACoAAFiDrz4Bns2yLsJGj_n4mQPA3ihv3zNbTGU | G270: 0 | H270: =(LEN(E270)-LEN(SUBSTITUTE(E270,"coursera","")))/LEN("coursera") -> 1 | I270: =(LEN(F270)-LEN(SUBSTITUTE(F270,"linkedin","")))/LEN("linkedin") -> 1 | J270: =SUM(H270:I270) -> 2
A271: 46032.965 | B271: aindrisingh1974@gmail.com | C271: Aindri Singh | D271: 102316039 | E271: https://drive.google.com/file/d/1tQ8XOEWgvlS-tJo0tOUmqYvBKX0j9YVd/view?usp=drive_link https://drive.google.com/file/d/1xHTNGb_D9ADiYUfvgSHwG4QmT1B20uX_/view?usp=drive_link | F271: https://www.linkedin.com/posts/aindri-singh-077816320_coursera-project-certificate-probability-activity-7415807676510547968-f0BE?utm_source=share&utm_medium=member_desktop&rcm=ACoAAFFHWdsBHJNWV43HrUee_sgBUVPLI6S6EII https://www.linkedin.com/posts/aindri-singh-077816320_coursera-project-certificate-working-with-activity-7415809257607966721-9e0l?utm_source=share&utm_medium=member_desktop&rcm=ACoAAFFHWdsBHJNWV43HrUee_sgBUVPLI6S6EII | G271: 0 | H271: =(LEN(E271)-LEN(SUBSTITUTE(E271,"coursera","")))/LEN("coursera") -> 0 | I271: =(LEN(F271)-LEN(SUBSTITUTE(F271,"linkedin","")))/LEN("linkedin") -> 2 | J271: =SUM(H271:I271) -> 2
A272: 46033.826 | B272: yraghuvanshi_be23@thapar.edu | C272: Yash Raghuvanshi | D272: 102303796 | E272: https://drive.google.com/drive/folders/1k4QgRCZRl8B7Wld-FqRNxX4GbeRfOciD?usp=sharing | F272: 1. https://www.linkedin.com/posts/yash-raghuvanshi-3b84772b9_tiet-thaparuniversity-thaparoutcomebasedlearning-activity-7415669255154651136-srJU?utm_source=share&utm_medium=member_desktop&rcm=ACoAAExr6HwBpexCFvMVL0OD0JPBIp75ryKltRg 2. https://www.linkedin.com/posts/yash-raghuvanshi-3b84772b9_tiet-thaparuniversity-thaparoutcomebasedlearning-activity-7416120654967619584-on7B?utm_source=share&utm_medium=member_desktop&rcm=ACoAAExr6HwBpexCFvMVL0OD0JPBIp75ryKltRg | G272: 0 | H272: =(LEN(E272)-LEN(SUBSTITUTE(E272,"coursera","")))/LEN("coursera") -> 0 | I272: =(LEN(F272)-LEN(SUBSTITUTE(F272,"linkedin","")))/LEN("linkedin") -> 2 | J272: =SUM(H272:I272) -> 2
A273: 46033.963 | B273: isharma1_be23@thapar.edu | C273: Ishaan Sharma | D273: 102303442 | E273: https://drive.google.com/drive/u/0/folders/16OEeq-nCt6GUSw4QkPIy2POLaLckUEJu | F273: https://www.linkedin.com/posts/ishaan-sharma-6062bb291_cicd-pipeline-with-docker-activity-7416170178566103041-YGq6?utm_source=social_share_send&utm_medium=member_desktop_web&rcm=ACoAAEazsKYBi0T6ljIH-Y9mP7fTUxEVx1gUlnM , https://www.linkedin.com/posts/ishaan-sharma-6062bb291_bigquery-activity-7416170365309181953-KBAs?utm_source=social_share_send&utm_medium=member_desktop_web&rcm=ACoAAEazsKYBi0T6ljIH-Y9mP7fTUxEVx1gUlnM | G273: 0 | H273: =(LEN(E273)-LEN(SUBSTITUTE(E273,"coursera","")))/LEN("coursera") -> 0 | I273: =(LEN(F273)-LEN(SUBSTITUTE(F273,"linkedin","")))/LEN("linkedin") -> 2 | J273: =SUM(H273:I273) -> 2
A274: 46033.964 | B274: bawejasargun@gmail.com | C274: Sargun Baweja | D274: 102317196 | E274: https://drive.google.com/drive/folders/13aNbLG7ZvurHIAsSvBAI-735ntw6OR4K?usp=sharing | F274: 1. https://www.linkedin.com/posts/sargunbaweja_tiet-thaparuniversity-thaparoutcomebasedlearning-activity-7416171229658763264-hBmE?utm_source=share&utm_medium=member_desktop&rcm=ACoAAEjUpF4BHQxkWbvpL-c-8g7lvfVMzLiAwew 2. https://www.linkedin.com/posts/sargunbaweja_tiet-thaparuniversity-thaparoutcomebasedlearning-activity-7416170339178606592-rAgG?utm_source=share&utm_medium=member_desktop&rcm=ACoAAEjUpF4BHQxkWbvpL-c-8g7lvfVMzLiAwew | G274: 0 | H274: =(LEN(E274)-LEN(SUBSTITUTE(E274,"coursera","")))/LEN("coursera") -> 0 | I274: =(LEN(F274)-LEN(SUBSTITUTE(F274,"linkedin","")))/LEN("linkedin") -> 2 | J274: =SUM(H274:I274) -> 2
A275: 46034.008 | B275: amehta_be23@thapar.edu | C275: Aarzoo Mehta | D275: 102303061 | E275: https://drive.google.com/file/d/1OWJHn_LDcwlqLKIG7d-RAI_DDcWD6XG8/view?usp=sharing, https://drive.google.com/file/d/1reMzJ26ETWDV5JlsWhEFbX_JIFoGKsr7/view?usp=sharing | F275: https://www.linkedin.com/posts/aarzoomehta152_tiet-thaparuniversity-coursera-activity-7416183936936067079-v6xd?utm_source=share&utm_medium=member_desktop&rcm=ACoAAEmyO2sBW_20q6BDV5sSbCQKIRTy0JIf2Qs , https://www.linkedin.com/posts/aarzoomehta152_tiet-thaparuniversity-coursera-activity-7416185642784694272-Lo5r?utm_source=share&utm_medium=member_desktop&rcm=ACoAAEmyO2sBW_20q6BDV5sSbCQKIRTy0JIf2Qs | G275: 0 | H275: =(LEN(E275)-LEN(SUBSTITUTE(E275,"coursera","")))/LEN("coursera") -> 0 | I275: =(LEN(F275)-LEN(SUBSTITUTE(F275,"linkedin","")))/LEN("linkedin") -> 2 | J275: =SUM(H275:I275) -> 2
A276: 46034.12 | B276: akshit.r.vats@gmail.com | C276: Akshit Vats | D276: 102317091 | E276: https://drive.google.com/file/d/1VTlHYnckvTTlVekW88AzowcUWUtA_KGp/view?usp=sharing https://drive.google.com/file/d/1H52ikKNHUkXDRz0EBWIPmkVtYwOK5TmB/view?usp=sharing | F276: https://www.linkedin.com/posts/akshitvats101_working-with-bigquery-activity-7416226105893867520-bMNX?utm_source=share&utm_medium=member_desktop&rcm=ACoAAETVRjABjbAGEpgrNlh_jIpds5ECaipYGJs https://www.linkedin.com/posts/akshitvats101_build-a-cicd-pipeline-with-docker-activity-7416224874852925441-g5kA?utm_source=share&utm_medium=member_desktop&rcm=ACoAAETVRjABjbAGEpgrNlh_jIpds5ECaipYGJs | G276: 0 | H276: =(LEN(E276)-LEN(SUBSTITUTE(E276,"coursera","")))/LEN("coursera") -> 0 | I276: =(LEN(F276)-LEN(SUBSTITUTE(F276,"linkedin","")))/LEN("linkedin") -> 2 | J276: =SUM(H276:I276) -> 2
A277: 46034.335 | B277: schhabra_be23@thapar.edu | C277: Samairaa Chhabra | D277: 102317219 | E277: https://drive.google.com/drive/folders/1F46GIiAeHV8bbkANxiCSBZ3CPGQG13Pb?usp=sharing | F277: https://www.linkedin.com/posts/samairaa-chhabra-8a5783304_completion-certificate-for-working-with-bigquery-activity-7416300482136162304-nWYI?utm_source=share&utm_medium=member_desktop&rcm=ACoAAE22dT0BXju90bF5rBOy-XHiWL4tTfu1jWc https://www.linkedin.com/posts/samairaa-chhabra-8a5783304_completion-certificate-for-working-with-bigquery-activity-7416300482136162304-nWYI?utm_source=share&utm_medium=member_desktop&rcm=ACoAAE22dT0BXju90bF5rBOy-XHiWL4tTfu1jWc | G277: 0 | H277: =(LEN(E277)-LEN(SUBSTITUTE(E277,"coursera","")))/LEN("coursera") -> 0 | I277: =(LEN(F277)-LEN(SUBSTITUTE(F277,"linkedin","")))/LEN("linkedin") -> 2 | J277: =SUM(H277:I277) -> 2
A278: 46041.587 | B278: asingh15_be23@thapar.edu | C278: Aindri Singh | D278: 102316039 | E278: https://drive.google.com/file/d/1u2jGu0bixFOfwbEsozM2HPa0yTjexxqI/view?usp=drive_link https://drive.google.com/file/d/1gG36J-sb_cBrGlnltboGZTxpsRakJNQt/view?usp=drive_link | F278: https://www.linkedin.com/posts/aindri-singh-077816320_coursera-project-certificate-google-analytics-activity-7418680578134310912-nwXc?utm_source=share&utm_medium=member_desktop&rcm=ACoAAFFHWdsBHJNWV43HrUee_sgBUVPLI6S6EII https://www.linkedin.com/posts/aindri-singh-077816320_coursera-project-certificate-emotion-recognition-activity-7418683828455596032-nQwm?utm_source=share&utm_medium=member_desktop&rcm=ACoAAFFHWdsBHJNWV43HrUee_sgBUVPLI6S6EII | G278: 0 | H278: =(LEN(E278)-LEN(SUBSTITUTE(E278,"coursera","")))/LEN("coursera") -> 0 | I278: =(LEN(F278)-LEN(SUBSTITUTE(F278,"linkedin","")))/LEN("linkedin") -> 2 | J278: =SUM(H278:I278) -> 2
...

Sheet Form Responses 1
A1: Timestamp | B1: Email Address | C1: Full Name of the Student | D1: Roll Number of the Student | E1: Coursera completion certificate link (Coursera Link only, no other text) (Certificate must shared in public mode) | F1: LinkedIn Post Link ( LinkedIn Link only, no other text) (Coursera Certificate must be shared on LinkedIn with your learning experience and following HashTags) #TIET #ThaparUniversity #ThaparOutcomeBasedLearning #ThaparCoursera #Coursera #UCS654_Predictive_Analytics | G1: Decision | H1: C1 | I1: C2 | J1: Total
A2: 46042.042 | B2: cgupta2_be23@thapar.edu | C2: Chirag Gupta | D2: 102303003 | E2: https://www.coursera.org/account/accomplishments/verify/Q8417WP3531Y | F2: https://www.linkedin.com/posts/chirag-gupta-73b17628a_bigquery-coursera-dataanalytics-activity-7416206744944672768-Acza?utm_source=share&utm_medium=member_desktop&rcm=ACoAAEYlz58BOR_5R6T4zKM0DTYwOi1oB-rz8Yo | G2: 1 | H2: =(LEN(E2)-LEN(SUBSTITUTE(E2,"coursera","")))/LEN("coursera") -> 1 | I2: =(LEN(F2)-LEN(SUBSTITUTE(F2,"linkedin","")))/LEN("linkedin") -> 1 | J2: =SUM(H2:I2) -> 2
A3: 46042.043 | B3: cgupta2_be23@thapar.edu | C3: Chirag Gupta | D3: 102303003 | E3: https://www.coursera.org/account/accomplishments/verify/L1N4IGVS0VHM | F3: https://www.linkedin.com/posts/chirag-gupta-73b17628a_docker-devops-cicd-activity-7416220181892354049-xxrj?utm_source=share&utm_medium=member_desktop&rcm=ACoAAEYlz58BOR_5R6T4zKM0DTYwOi1oB-rz8Yo | G3: 1 | H3: =(LEN(E3)-LEN(SUBSTITUTE(E3,"coursera","")))/LEN("coursera") -> 1 | I3: =(LEN(F3)-LEN(SUBSTITUTE(F3,"linkedin","")))/LEN("linkedin") -> 1 | J3: =SUM(H3:I3) -> 2
A4: 46042.044 | B4: cgupta2_be23@thapar.edu | C4: Chirag Gupta | D4: 102303003 | E4: https://www.coursera.org/account/accomplishments/verify/8BY3D4KJFOIN | F4: https://www.linkedin.com/posts/chirag-gupta-73b17628a_sql-postgresql-dataanalytics-activity-7418891807712944128-lkgO?utm_source=share&utm_medium=member_desktop&rcm=ACoAAEYlz58BOR_5R6T4zKM0DTYwOi1oB-rz8Yo | G4: 1 | H4: =(LEN(E4)-LEN(SUBSTITUTE(E4,"coursera","")))/LEN("coursera") -> 1 | I4: =(LEN(F4)-LEN(SUBSTITUTE(F4,"linkedin","")))/LEN("linkedin") -> 1 | J4: =SUM(H4:I4) -> 2
A5: 46042.045 | B5: cgupta2_be23@thapar.edu | C5: Chirag Gupta | D5: 102303003 | E5: https://www.coursera.org/account/accomplishments/verify/WT0NVE758KJA | F5: https://www.linkedin.com/posts/chirag-gupta-73b17628a_tiet-thaparuniversity-thaparoutcomebasedlearning-activity-7419037784130215936-KbmF?utm_source=share&utm_medium=member_desktop&rcm=ACoAAEYlz58BOR_5R6T4zKM0DTYwOi1oB-rz8Yo | G5: 1 | H5: =(LEN(E5)-LEN(SUBSTITUTE(E5,"coursera","")))/LEN("coursera") -> 1 | I5: =(LEN(F5)-LEN(SUBSTITUTE(F5,"linkedin","")))/LEN("linkedin") -> 1 | J5: =SUM(H5:I5) -> 2
A6: 46041.494 | B6: nsharma3_be23@thapar.edu | C6: Nihar Sharma | D6: 102303012 | E6: https://coursera.org/share/e8e72de68d980893288eb72a7f4a323c | F6: https://www.linkedin.com/posts/itsniharsharma_tiet-thaparuniversity-thaparoutcomebasedlearning-activity-7416206081934270464-zqae?utm_source=share&utm_medium=member_desktop&rcm=ACoAAEUJVJIB7LFMYCH-08-vKr7qIY-tWbfVVoE | G6: 1 | H6: =(LEN(E6)-LEN(SUBSTITUTE(E6,"coursera","")))/LEN("coursera") -> 1 | I6: =(LEN(F6)-LEN(SUBSTITUTE(F6,"linkedin","")))/LEN("linkedin") -> 1 | J6: =SUM(H6:I6) -> 2
A7: 46041.495 | B7: nsharma3_be23@thapar.edu | C7: Nihar Sharma | D7: 102303012 | E7: https://coursera.org/share/1063b2bdaf9c002125e4f5983dee3f52 | F7: https://www.linkedin.com/posts/itsniharsharma_tiet-thaparinstitute-thaparuniversity-activity-7416198699195793408-tDMK?utm_source=share&utm_medium=member_desktop&rcm=ACoAAEUJVJIB7LFMYCH-08-vKr7qIY-tWbfVVoE | G7: 1 | H7: =(LEN(E7)-LEN(SUBSTITUTE(E7,"coursera","")))/LEN("coursera") -> 1 | I7: =(LEN(F7)-LEN(SUBSTITUTE(F7,"linkedin","")))/LEN("linkedin") -> 1 | J7: =SUM(H7:I7) -> 2
A8: 46034.859 | B8: mohammadaaban4@gmail.com | C8: Mohammad Aaban | D8: 102303015 | E8: https://coursera.org/share/44bc8826138092def5df3b862872731e | F8: https://www.linkedin.com/posts/mohammad-aaban-347139293_build-a-cicd-pipeline-with-docker-project-activity-7416494245739380737-HM4r?utm_source=share&utm_medium=member_desktop&rcm=ACoAAEcIbacBeos04Hgiqu9yZcGLBuNX4fz_GMg | G8: 1 | H8: =(LEN(E8)-LEN(SUBSTITUTE(E8,"coursera","")))/LEN("coursera") -> 1 | I8: =(LEN(F8)-LEN(SUBSTITUTE(F8,"linkedin","")))/LEN("linkedin") -> 1 | J8: =SUM(H8:I8) -> 2
A9: 46034.859 | B9: mohammadaaban4@gmail.com | C9: Mohammad Aaban | D9: 102303015 | E9: https://coursera.org/share/fbcd368d5a95cb4181774d2dcebfa6c3 | F9: https://www.linkedin.com/posts/mohammad-aaban-347139293_working-with-bigquery-coursera-certificate-activity-7416491683887886336--G-9?utm_source=share&utm_medium=member_desktop&rcm=ACoAAEcIbacBeos04Hgiqu9yZcGLBuNX4fz_GMg | G9: 1 | H9: =(LEN(E9)-LEN(SUBSTITUTE(E9,"coursera","")))/LEN("coursera") -> 1 | I9: =(LEN(F9)-LEN(SUBSTITUTE(F9,"linkedin","")))/LEN("linkedin") -> 1 | J9: =SUM(H9:I9) -> 2
A10: 46042.977 | B10: maaban_be23@thapar.edu | C10: Mohammad Aaban | D10: 102303015 | E10: https://coursera.org/share/b988f48a7958d1ec8fcaf7b9126afd18 | F10: https://www.linkedin.com/posts/mohammad-aaban-347139293_coursera-certificate-activity-7419436869181976577-EIrR?utm_source=share&utm_medium=member_desktop&rcm=ACoAAEcIbacBeos04Hgiqu9yZcGLBuNX4fz_GMg | G10: 1 | H10: =(LEN(E10)-LEN(SUBSTITUTE(E10,"coursera","")))/LEN("coursera") -> 1 | I10: =(LEN(F10)-LEN(SUBSTITUTE(F10,"linkedin","")))/LEN("linkedin") -> 1 | J10: =SUM(H10:I10) -> 2
A11: 46042.98 | B11: maaban_be23@thapar.edu | C11: Mohammad Aaban | D11: 102303015 | E11: https://coursera.org/share/c76eff20b0b3cad08437acc845b8997a | F11: https://www.linkedin.com/posts/mohammad-aaban-347139293_coursera-certificate-ugcPost-7419438687538765825-CHge?utm_source=share&utm_medium=member_desktop&rcm=ACoAAEcIbacBeos04Hgiqu9yZcGLBuNX4fz_GMg | G11: 1 | H11: =(LEN(E11)-LEN(SUBSTITUTE(E11,"coursera","")))/LEN("coursera") -> 1 | I11: =(LEN(F11)-LEN(SUBSTITUTE(F11,"linkedin","")))/LEN("linkedin") -> 1 | J11: =SUM(H11:I11) -> 2
A12: 46050.381 | B12: mohammadaaban4@gmail.com | C12: Mohammad Aaban | D12: 102303015 | E12: https://coursera.org/share/24cbd6e172970ea7609550e9a6920817 | F12: https://www.linkedin.com/posts/mohammad-aaban-347139293_coursera-certificate-ugcPost-7422120722183036928-PPRD?utm_source=share&utm_medium=member_desktop&rcm=ACoAAEcIbacBeos04Hgiqu9yZcGLBuNX4fz_GMg | G12: 1 | H12: =(LEN(E12)-LEN(SUBSTITUTE(E12,"coursera","")))/LEN("coursera") -> 1 | I12: =(LEN(F12)-LEN(SUBSTITUTE(F12,"linkedin","")))/LEN("linkedin") -> 1 | J12: =SUM(H12:I12) -> 2
A13: 46050.383 | B13: mohammadaaban4@gmail.com | C13: Mohammad Aaban | D13: 102303015 | E13: https://coursera.org/share/ee4d20e18e0c1250794c1893ca0ce16c | F13: https://www.linkedin.com/posts/mohammad-aaban-347139293_coursera-certificate-ugcPost-7422121406282510337-1RwQ?utm_source=share&utm_medium=member_desktop&rcm=ACoAAEcIbacBeos04Hgiqu9yZcGLBuNX4fz_GMg | G13: 1 | H13: =(LEN(E13)-LEN(SUBSTITUTE(E13,"coursera","")))/LEN("coursera") -> 1 | I13: =(LEN(F13)-LEN(SUBSTITUTE(F13,"linkedin","")))/LEN("linkedin") -> 1 | J13: =SUM(H13:I13) -> 2
... A2314: 46054.8 | B2314: asaini2_be23@thapar.edu | C2314: Aryan Saini | D2314: 102303666 | E2314: https://coursera.org/share/a5638342b1876907589b575db3196870 | F2314: https://www.linkedin.com/posts/aryan-saini-970456323_investment-risk-management-project-certificate-ugcPost-7423721568222158848-dxFZ?utm_source=share&utm_medium=member_desktop&rcm=ACoAAFHCIuQBMi1oWc4cnsVdmF4C170qrppvLD0 | G2314: 1 | H2314: =(LEN(E2314)-LEN(SUBSTITUTE(E2314,"coursera","")))/LEN("coursera") -> 1 | I2314: =(LEN(F2314)-LEN(SUBSTITUTE(F2314,"linkedin","")))/LEN("linkedin") -> 1 | J2314: =SUM(H2314:I2314) -> 2
A2315: 46054.804 | B2315: hmalhotra_be23@thapar.edu | C2315: Harina Malhotra | D2315: 102303232 | E2315: https://www.coursera.org/account/accomplishments/verify/MHWPEED380B8 | F2315: https://www.linkedin.com/posts/harina-malhotra-705438287_microsoftexcel-dataanalysis-excelskills-activity-7423723186250432512-CpDZ?utm_source=share&utm_medium=member_desktop&rcm=ACoAAEWnTPUBZNrKl9eNk1hGg2zpPY6TVqgwkrg
A2316: 46054.804 | B2316: hmalhotra_be23@thapar.edu | C2316: Harina Malhotra | D2316: 102303232 | E2316: https://www.coursera.org/account/accomplishments/verify/LPXF31S051HU | F2316: https://www.linkedin.com/posts/harina-malhotra-705438287_microsoftexcel-dataanalysis-excelskills-activity-7423723186250432512-CpDZ?utm_source=share&utm_medium=member_desktop&rcm=ACoAAEWnTPUBZNrKl9eNk1hGg2zpPY6TVqgwkrg
A2317: 46054.81 | B2317: dmalik_be23@thapar.edu | C2317: Disha Malik | D2317: 102303141 | E2317: https://coursera.org/share/04f1bb1a48ca5f84d97b639e0c5d6fe0 | F2317: https://www.linkedin.com/posts/disha-m10_tiet-thaparinstitute-thaparuniversity-share-7423722786273042432-roWc?utm_source=share&utm_medium=member_desktop&rcm=ACoAAEhseuYBaaSfNqUVz6tXTFML4Vup5z-pplA
A2318: 46054.811 | B2318: ngupta2_be23@thapar.edu | C2318: Nishtha Gupta | D2318: 102303998 | E2318: https://coursera.org/share/e27989ad9fe9c881e6e4fc9b8ead8ddc | F2318: https://www.linkedin.com/posts/nishtha-gupta-55750a2b1_completion-certificate-for-working-with-bigquery-activity-7416170768880943104-oR0R?utm_source=share&utm_medium=member_desktop&rcm=ACoAAEsBEpMBTrVD_085LQRwt-583-zUY-pKn0Q
A2319: 46054.811 | B2319: hkansal_be23@thapar.edu | C2319: HARSHIT KANSAL | D2319: 102303554 | E2319: https://coursera.org/share/0867fe849985129345728cd442428ecc | F2319: https://www.linkedin.com/posts/harshit-kansal-682949349_tiet-thaparuniversity-thaparoutcomebasedlearning-activity-7423726075421188096-Ad99?utm_source=share&utm_medium=member_desktop&rcm=ACoAAFcrwIIBHhnWDLBHrVvK9jjoG-jVrlaomTE
A2320: 46054.811 | B2320: dmalik_be23@thapar.edu | C2320: Disha Malik | D2320: 102303141 | E2320: https://coursera.org/share/67a34662f54963e68d99f4dc268fc4e0 | F2320: https://www.linkedin.com/posts/disha-m10_tiet-thaparinstitute-thaparuniversity-share-7423724123433975808-WC-D?utm_source=share&utm_medium=member_desktop&rcm=ACoAAEhseuYBaaSfNqUVz6tXTFML4Vup5z-pplA
A2321: 46054.811 | B2321: ngupta2_be23@thapar.edu | C2321: Nishtha Gupta | D2321: 102303998 | E2321: https://coursera.org/share/d13042b0ddded3248cf4822c4f1ca5d6 | F2321: https://www.linkedin.com/posts/nishtha-gupta-55750a2b1_completion-certificate-for-build-a-cicd-activity-7416172453057572864-vYgo?utm_source=share&utm_medium=member_desktop&rcm=ACoAAEsBEpMBTrVD_085LQRwt-583-zUY-pKn0Q
A2322: 46054.812 | B2322: dmalik_be23@thapar.edu | C2322: Disha Malik | D2322: 102303141 | E2322: https://coursera.org/share/5c5fb56e0795dcc3c4ed99652490a455 | F2322: https://www.linkedin.com/posts/disha-m10_tiet-thaparinstitute-thaparuniversity-share-7423723415188000768-2hC6?utm_source=share&utm_medium=member_desktop&rcm=ACoAAEhseuYBaaSfNqUVz6tXTFML4Vup5z-pplA
A2323: 46054.812 | B2323: dmalik_be23@thapar.edu | C2323: Disha Malik | D2323: 102303141 | E2323: https://coursera.org/share/22c8135ce026bb0f4a218099b87c22f0 | F2323: https://www.linkedin.com/posts/disha-m10_tiet-thaparinstitute-thaparuniversity-share-7423724629741150208-p9ia?utm_source=share&utm_medium=member_desktop&rcm=ACoAAEhseuYBaaSfNqUVz6tXTFML4Vup5z-pplA
A2324: 46054.812 | B2324: lbhatia_be23@thapar.edu | C2324: Lovepreet Bhatia | D2324: 102303335 | E2324: https://coursera.org/share/4a5df9ee5233eff0d3d3828076afcc2d | F2324: https://www.linkedin.com/posts/lovepreet-bhatia-16a66838b_working-with-bigquery-activity-7415808589497282560-Y8uH/?utm_source=share&utm_medium=member_desktop&rcm=ACoAAGAt5fMBGFx611lB_AIC3jzy0T1_acWPX8g
A2325: 46054.813 | B2325: dmalik_be23@thapar.edu | C2325: Disha Malik | D2325: 102303141 | E2325: https://coursera.org/share/71b9e6a2e26ecd53c37cccfd27f6c24e | F2325: https://www.linkedin.com/posts/disha-m10_tiet-thaparinstitute-thaparuniversity-share-7423725380508860416-2AGQ?utm_source=share&utm_medium=member_desktop&rcm=ACoAAEhseuYBaaSfNqUVz6tXTFML4Vup5z-pplA
A2326: 46054.814 | B2326: hkansal_be23@thapar.edu | C2326: HARSHIT KANSAL | D2326: 102303554 | E2326: https://coursera.org/share/e127e1ad3ba0547e2b7b681f9ad857eb | F2326: https://www.linkedin.com/posts/harshit-kansal-682949349_completion-certificate-for-tweet-emotion-activity-7423726870564855808-Gc_k?utm_source=share&utm_medium=member_desktop&rcm=ACoAAFcrwIIBHhnWDLBHrVvK9jjoG-jVrlaomTE
... A2447: 46054.909 | B2447: dsingh2_be23@thapar.edu | C2447: Danishdeep Singh | D2447: 102317073 | E2447: https://www.coursera.org/account/accomplishments/certificate/1J929NITDM9G | F2447: https://www.linkedin.com/feed/update/urn:li:activity:7423760780040527872/
